2024-10-10 13:12:19.368 | INFO     | aiogram.dispatcher.dispatcher:start_polling:359 - Start polling.
2024-10-10 13:12:20.835 | INFO     | aiogram.contrib.middlewares.logging:on_pre_process_message:36 - Received message [ID:40] in chat [private:5213841899]
2024-10-10 13:12:21.084 | INFO     | aiogram.contrib.middlewares.logging:on_pre_process_error:150 - Process update [ID:728620766]: [failed] (in 249 ms)
2024-10-10 13:12:27.054 | ERROR    | asyncio.base_events:default_exception_handler:1771 - Task exception was never retrieved
future: <Task finished name='Task-374' coro=<Dispatcher._process_polling_updates() done, defined at C:\Users\net\AppData\Local\Programs\Python\Python311\Lib\site-packages\aiogram\dispatcher\dispatcher.py:410> exception=ChatNotFound('Chat not found')>
Traceback (most recent call last):

> File "C:\Users\net\AppData\Local\Programs\Python\Python311\Lib\site-packages\aiogram\dispatcher\dispatcher.py", line 418, in _process_polling_updates
    for responses in itertools.chain.from_iterable(await self.process_updates(updates, fast)):
                     │         │     │                   │    │               │        └ True
                     │         │     │                   │    │               └ [<Update {"update_id":728620766,"message":{"message_id":40,"from":{"id":5213841899,"is_bot":false,"first_name":"Антон","usern...
                     │         │     │                   │    └ <function Dispatcher.process_updates at 0x00000218FD8644A0>
                     │         │     │                   └ <aiogram.dispatcher.dispatcher.Dispatcher object at 0x00000218FD4D6550>
                     │         │     └ <method 'from_iterable' of 'itertools.chain' objects>
                     │         └ <class 'itertools.chain'>
                     └ <module 'itertools' (built-in)>
  File "C:\Users\net\AppData\Local\Programs\Python\Python311\Lib\site-packages\aiogram\dispatcher\dispatcher.py", line 236, in process_updates
    return await asyncio.gather(*tasks)
                 │       │       └ [<coroutine object Handler.notify at 0x00000218FDDF8400>]
                 │       └ <function gather at 0x00000218FBE03240>
                 └ <module 'asyncio' from 'C:\\Users\\net\\AppData\\Local\\Programs\\Python\\Python311\\Lib\\asyncio\\__init__.py'>
  File "C:\Users\net\AppData\Local\Programs\Python\Python311\Lib\site-packages\aiogram\dispatcher\handler.py", line 117, in notify
    response = await handler_obj.handler(*args, **partial_data)
                     │           │        │       └ {}
                     │           │        └ (<Update {"update_id":728620766,"message":{"message_id":40,"from":{"id":5213841899,"is_bot":false,"first_name":"Антон","usern...
                     │           └ <bound method Dispatcher.process_update of <aiogram.dispatcher.dispatcher.Dispatcher object at 0x00000218FD4D6550>>
                     └ Handler.HandlerObj(handler=<bound method Dispatcher.process_update of <aiogram.dispatcher.dispatcher.Dispatcher object at 0x0...
  File "C:\Users\net\AppData\Local\Programs\Python\Python311\Lib\site-packages\aiogram\dispatcher\dispatcher.py", line 257, in process_update
    return await self.message_handlers.notify(update.message)
                 │    │                │      │      └ <aiogram.types.fields.Field object at 0x00000218FD6E9490>
                 │    │                │      └ <Update {"update_id":728620766,"message":{"message_id":40,"from":{"id":5213841899,"is_bot":false,"first_name":"Антон","userna...
                 │    │                └ <function Handler.notify at 0x00000218FD772AC0>
                 │    └ <aiogram.dispatcher.handler.Handler object at 0x00000218FDC2DC50>
                 └ <aiogram.dispatcher.dispatcher.Dispatcher object at 0x00000218FD4D6550>
  File "C:\Users\net\AppData\Local\Programs\Python\Python311\Lib\site-packages\aiogram\dispatcher\handler.py", line 117, in notify
    response = await handler_obj.handler(*args, **partial_data)
                     │           │        │       └ {'state': <aiogram.dispatcher.storage.FSMContext object at 0x00000218FF0378D0>}
                     │           │        └ (<Message {"message_id":40,"from":{"id":5213841899,"is_bot":false,"first_name":"Антон","username":"neboltavau","language_code...
                     │           └ <function start_message at 0x00000218FDB74E00>
                     └ Handler.HandlerObj(handler=<function start_message at 0x00000218FDB74E00>, spec=FullArgSpec(args=['message', 'state'], vararg...

  File "f:\shopbot\handlers\common.py", line 173, in start_message
    await message.forward(config.links.forward_channel_id)
          │       │       │      │     └ -1001687848928
          │       │       │      └ Links(forward_channel_id=-1001687848928, zalets_channel_id=-1001730947390, reviews_channel_url='https://t.me/+U9ls4-OkejowMWV...
          │       │       └ Config(tg=Telegram(token='7774045102:AAGxE103tpOlQKWOW3IVPbopmk6yCGzOJMI', admin_id=52138418992), links=Links(forward_channel...
          │       └ <function Message.forward at 0x00000218FD6A1A80>
          └ <Message {"message_id":40,"from":{"id":5213841899,"is_bot":false,"first_name":"Антон","username":"neboltavau","language_code"...

  File "C:\Users\net\AppData\Local\Programs\Python\Python311\Lib\site-packages\aiogram\types\message.py", line 2876, in forward
    return await self.bot.forward_message(
                 │    └ <property object at 0x00000218FD4DF010>
                 └ <Message {"message_id":40,"from":{"id":5213841899,"is_bot":false,"first_name":"Антон","username":"neboltavau","language_code"...
  File "C:\Users\net\AppData\Local\Programs\Python\Python311\Lib\site-packages\aiogram\bot\bot.py", line 394, in forward_message
    result = await self.request(api.Methods.FORWARD_MESSAGE, payload)
                   │    │       │   │       │                └ {'chat_id': -1001687848928, 'from_chat_id': 5213841899, 'message_id': 40}
                   │    │       │   │       └ <aiogram.utils.helper.Item object at 0x00000218FD6EB8D0>
                   │    │       │   └ <class 'aiogram.bot.api.Methods'>
                   │    │       └ <module 'aiogram.bot.api' from 'C:\\Users\\net\\AppData\\Local\\Programs\\Python\\Python311\\Lib\\site-packages\\aiogram\\bot...
                   │    └ <function BaseBot.request at 0x00000218FD70F740>
                   └ <aiogram.bot.bot.Bot object at 0x00000218FDAF5610>
  File "C:\Users\net\AppData\Local\Programs\Python\Python311\Lib\site-packages\aiogram\bot\base.py", line 236, in request
    return await api.make_request(await self.get_session(), self.server, self.__token, method, data, files,
                 │   │                  │    │              │    │       │             │       │     └ None
                 │   │                  │    │              │    │       │             │       └ {'chat_id': -1001687848928, 'from_chat_id': 5213841899, 'message_id': 40}
                 │   │                  │    │              │    │       │             └ 'forwardMessage'
                 │   │                  │    │              │    │       └ <aiogram.bot.bot.Bot object at 0x00000218FDAF5610>
                 │   │                  │    │              │    └ TelegramAPIServer(base='https://api.telegram.org/bot{token}/{method}', file='https://api.telegram.org/file/bot{token}/{path}')
                 │   │                  │    │              └ <aiogram.bot.bot.Bot object at 0x00000218FDAF5610>
                 │   │                  │    └ <function BaseBot.get_session at 0x00000218FD70EF20>
                 │   │                  └ <aiogram.bot.bot.Bot object at 0x00000218FDAF5610>
                 │   └ <function make_request at 0x00000218FD6CE480>
                 └ <module 'aiogram.bot.api' from 'C:\\Users\\net\\AppData\\Local\\Programs\\Python\\Python311\\Lib\\site-packages\\aiogram\\bot...
  File "C:\Users\net\AppData\Local\Programs\Python\Python311\Lib\site-packages\aiogram\bot\api.py", line 140, in make_request
    return check_result(method, response.content_type, response.status, await response.text())
           │            │       │        │             │        │             │        └ <function ClientResponse.text at 0x00000218FC7EAAC0>
           │            │       │        │             │        │             └ <ClientResponse(https://api.telegram.org/bot7774045102:AAGxE103tpOlQKWOW3IVPbopmk6yCGzOJMI/forwardMessage) [400 Bad Request]>...
           │            │       │        │             │        └ 400
           │            │       │        │             └ <ClientResponse(https://api.telegram.org/bot7774045102:AAGxE103tpOlQKWOW3IVPbopmk6yCGzOJMI/forwardMessage) [400 Bad Request]>...
           │            │       │        └ <property object at 0x00000218FC738B30>
           │            │       └ <ClientResponse(https://api.telegram.org/bot7774045102:AAGxE103tpOlQKWOW3IVPbopmk6yCGzOJMI/forwardMessage) [400 Bad Request]>...
           │            └ 'forwardMessage'
           └ <function check_result at 0x00000218FD6CE5C0>
  File "C:\Users\net\AppData\Local\Programs\Python\Python311\Lib\site-packages\aiogram\bot\api.py", line 115, in check_result
    exceptions.BadRequest.detect(description)
    │          │          │      └ 'Bad Request: chat not found'
    │          │          └ <classmethod(<function _MatchErrorMixin.detect at 0x00000218FD4BF880>)>
    │          └ <class 'aiogram.utils.exceptions.BadRequest'>
    └ <module 'aiogram.utils.exceptions' from 'C:\\Users\\net\\AppData\\Local\\Programs\\Python\\Python311\\Lib\\site-packages\\aio...
  File "C:\Users\net\AppData\Local\Programs\Python\Python311\Lib\site-packages\aiogram\utils\exceptions.py", line 140, in detect
    raise err(cls.text or description)
          │   │   │       └ 'bad request: chat not found'
          │   │   └ None
          │   └ <class 'aiogram.utils.exceptions.BadRequest'>
          └ <class 'aiogram.utils.exceptions.ChatNotFound'>

aiogram.utils.exceptions.ChatNotFound: Chat not found
2024-10-10 13:12:27.074 | INFO     | aiogram.contrib.middlewares.logging:on_pre_process_message:36 - Received message [ID:41] in chat [private:5213841899]
2024-10-10 13:12:27.329 | INFO     | aiogram.contrib.middlewares.logging:on_pre_process_error:150 - Process update [ID:728620767]: [failed] (in 256 ms)
